<?xml version="1.0" encoding="utf-8"?>
<!-- This URDF was automatically created by SolidWorks to URDF Exporter! Originally created by Stephen Brawner (brawner@gmail.com) 
     Commit Version: 1.6.0-4-g7f85cfe  Build Version: 1.6.7995.38578
     For more information, please see http://wiki.ros.org/sw_urdf_exporter -->
<robot
  name="mars_rover">
  <link
    name="base_rover_1">
    <inertial>
      <origin
        xyz="0 0 0"
        rpy="0 0 0" />
      <mass
        value="2.8" />
      <inertia ixx="0.095684"
               ixy="0"
               ixz="-0.00027184"
               iyy="0"
               iyz="0"
               izz="0.14455" />
    </inertial>
    <visual>
      <origin
        xyz="0 0 0"
        rpy="0 0 0" />
      <geometry>
        <mesh
          filename="package://mars_rover/meshes/base_rover_1.STL" />
      </geometry>
      <material
        name="">
        <color
          rgba="0.792156862745098 0.819607843137255 0.933333333333333 1" />
      </material>
    </visual>
    <collision>
      <origin
        xyz="0 0 0"
        rpy="0 0 0" />
      <geometry>
        <mesh
          filename="package://mars_rover/meshes/base_rover_1.STL" />
      </geometry>
    </collision>
  </link>


  <link
    name="wheel_1">
    <inertial>
      <origin
        xyz="-0.063397 -4.4964E-15 1.4988E-15"
        rpy="0 0 0" />
      <mass
        value="6.4993" />
      <inertia
        ixx="0.062324"
        ixy="4.8469E-07"
        ixz="-1.0587E-06"
        iyy="0.037901"
        iyz="6.9389E-18"
        izz="0.037901" />
    </inertial>
    <visual>
      <origin
        xyz="0 0 0"
        rpy="0 0 0" />
      <geometry>
        <mesh
          filename="package://mars_rover/meshes/wheel_1.STL" />
      </geometry>
      <material
        name="">
        <color
          rgba="1 0 0 1" />
      </material>
    </visual>
    <collision>
      <origin
        xyz="0 0 0"
        rpy="0 0 0" />
      <geometry>
        <mesh
          filename="package://mars_rover/meshes/wheel_1.STL" />
      </geometry>
            <surface>
        <bounce>
          <restitution_coefficient>0.1</restitution_coefficient>
          <threshold>0</threshold>
        </bounce>
        <contact>
          <ode>
            <max_vel>0.2</max_vel>
          </ode>
        </contact>
      </surface>
    </collision>
  </link>
  <joint
    name="joint_w1"
    type="continuous">
    <origin
      xyz="0.373705519949924 -0.333276944984588 -0.0128821732436576"
      rpy="-2.57071455235077 0 1.5707963267949" />
    <parent
      link="base_rover_1" />
    <child
      link="wheel_1" />
    <axis
      xyz="1 0 0" />
  </joint>
  <link
    name="wheel_2">
    <inertial>
      <origin
        xyz="-0.063397 3.9968E-15 9.253E-10"
        rpy="0 0 0" />
      <mass
        value="6.4993" />
      <inertia
        ixx="0.062324"
        ixy="-1.1644E-06"
        ixz="-6.9654E-10"
        iyy="0.037901"
        iyz="1.6994E-14"
        izz="0.037901" />
    </inertial>
    <visual>
      <origin
        xyz="0 0 0"
        rpy="0 0 0" />
      <geometry>
        <mesh
          filename="package://mars_rover/meshes/wheel_2.STL" />
      </geometry>
      <material
        name="">
        <color
          rgba="0.79216 0.81961 0.93333 1" />
      </material>
    </visual>
    <collision>
      <origin
        xyz="0 0 0"
        rpy="0 0 0" />
      <geometry>
        <mesh
          filename="package://mars_rover/meshes/wheel_2.STL" />
      </geometry>
            <surface>
        <bounce>
          <restitution_coefficient>0.1</restitution_coefficient>
          <threshold>0</threshold>
        </bounce>
        <contact>
          <ode>
            <max_vel>0.2</max_vel>
          </ode>
        </contact>
      </surface>
    </collision>
  </link>
  <joint
    name="joint_w2"
    type="continuous">
    <origin
      xyz="-0.0882727119071309 -0.333276944984562 -0.0481207258492364"
      rpy="-0.0485724166465315 0 1.57079632750354" />
    <parent
      link="base_rover_1" />
    <child
      link="wheel_2" />
    <axis
      xyz="1 0 0" />
  </joint>
  <link
    name="wheel_3">
    <inertial>
      <origin
        xyz="-0.063397 1.9467E-13 -1.3256E-13"
        rpy="0 0 0" />
      <mass
        value="6.4993" />
      <inertia
        ixx="0.062324"
        ixy="-1.1644E-06"
        ixz="-3.4009E-10"
        iyy="0.037901"
        iyz="2.1249E-20"
        izz="0.037901" />
    </inertial>
    <visual>
      <origin
        xyz="0 0 0"
        rpy="0 0 0" />
      <geometry>
        <mesh
          filename="package://mars_rover/meshes/wheel_3.STL" />
      </geometry>
      <material
        name="">
        <color
          rgba="0.79216 0.81961 0.93333 1" />
      </material>
    </visual>
    <collision>
      <origin
        xyz="0 0 0"
        rpy="0 0 0" />
      <geometry>
        <mesh
          filename="package://mars_rover/meshes/wheel_3.STL" />
      </geometry>

            <surface>
        <bounce>
          <restitution_coefficient>0.1</restitution_coefficient>
          <threshold>0</threshold>
        </bounce>
        <contact>
          <ode>
            <max_vel>0.2</max_vel>
          </ode>
        </contact>
      </surface>
    </collision>
  </link>
  <joint
    name="joint_w3"
    type="continuous">
    <origin
      xyz="-0.441256611089257 -0.333276944984561 -0.0514922118987491"
      rpy="1.5707963267949 0 1.5707963267949" />
    <parent
      link="base_rover_1" />
    <child
      link="wheel_3" />
    <axis
      xyz="1 0 0" />
  </joint>
  <link
    name="wheel_4">
    <inertial>
      <origin
        xyz="0.060603 -1.3294E-13 -3.9635E-14"
        rpy="0 0 0" />
      <mass
        value="6.4993" />
      <inertia
        ixx="0.062324"
        ixy="8.2245E-07"
        ixz="8.2424E-07"
        iyy="0.037901"
        iyz="-2.6021E-18"
        izz="0.037901" />
    </inertial>
    <visual>
      <origin
        xyz="0 0 0"
        rpy="0 0 0" />
      <geometry>
        <mesh
          filename="package://mars_rover/meshes/wheel_4.STL" />
      </geometry>
      <material
        name="">
        <color
          rgba="0.79216 0.81961 0.93333 1" />
      </material>
    </visual>
    <collision>
      <origin
        xyz="0 0 0"
        rpy="0 0 0" />
      <geometry>
        <mesh
          filename="package://mars_rover/meshes/wheel_4.STL" />
      </geometry>

            <surface>
        <bounce>
          <restitution_coefficient>0.1</restitution_coefficient>
          <threshold>0</threshold>
        </bounce>
        <contact>
          <ode>
            <max_vel>0.2</max_vel>
          </ode>
        </contact>
      </surface>
    </collision>
  </link>
  <joint
    name="joint_w4"
    type="continuous">
    <origin
      xyz="0.349142456408795 -1.29967694498458 -0.0366791162624158"
      rpy="-1.96389113722142 0 -1.5707963267949" />
    <parent
      link="base_rover_1" />
    <child
      link="wheel_4" />
    <axis
      xyz="-1 0 0" />
  </joint>
  <link
    name="wheel_5">
    <inertial>
      <origin
        xyz="0.060603 2.1788E-14 1.6598E-14"
        rpy="0 0 0" />
      <mass
        value="6.4993" />
      <inertia
        ixx="0.062324"
        ixy="8.2245E-07"
        ixz="8.2424E-07"
        iyy="0.037901"
        iyz="-8.6736E-19"
        izz="0.037901" />
    </inertial>
    <visual>
      <origin
        xyz="0 0 0"
        rpy="0 0 0" />
      <geometry>
        <mesh
          filename="package://mars_rover/meshes/wheel_5.STL" />
      </geometry>
      <material
        name="">
        <color
          rgba="0.79216 0.81961 0.93333 1" />
      </material>
    </visual>
    <collision>
      <origin
        xyz="0 0 0"
        rpy="0 0 0" />
      <geometry>
        <mesh
          filename="package://mars_rover/meshes/wheel_5.STL" />
      </geometry>
            <surface>
        <bounce>
          <restitution_coefficient>0.1</restitution_coefficient>
          <threshold>0</threshold>
        </bounce>
        <contact>
          <ode>
            <max_vel>0.2</max_vel>
          </ode>
        </contact>
      </surface>
    </collision>
  </link>
  <joint
    name="joint_w5"
    type="continuous">
    <origin
      xyz="-0.0856865365698763 -1.29967694498458 -0.00527252429838212"
      rpy="-1.96389113722143 0 -1.5707963267949" />
    <parent
      link="base_rover_1" />
    <child
      link="wheel_5" />
    <axis
      xyz="-1 0 0" />
  </joint>
  <link
    name="wheel_6">
    <inertial>
      <origin
        xyz="0.060603 1.4413E-13 8.2656E-14"
        rpy="0 0 0" />
      <mass
        value="6.4993" />
      <inertia
        ixx="0.062324"
        ixy="8.2245E-07"
        ixz="8.2424E-07"
        iyy="0.037901"
        iyz="-3.4694E-18"
        izz="0.037901" />
    </inertial>
    <visual>
      <origin
        xyz="0 0 0"
        rpy="0 0 0" />
      <geometry>
        <mesh
          filename="package://mars_rover/meshes/wheel_6.STL" />
      </geometry>
      <material
        name="">
        <color
          rgba="0.79216 0.81961 0.93333 1" />
      </material>
    </visual>
    <collision>
      <origin
        xyz="0 0 0"
        rpy="0 0 0" />
      <geometry>
        <mesh
          filename="package://mars_rover/meshes/wheel_6.STL" />
      </geometry>
            <surface>
        <bounce>
          <restitution_coefficient>0.1</restitution_coefficient>
          <threshold>0</threshold>
        </bounce>
        <contact>
          <ode>
            <max_vel>0.2</max_vel>
          </ode>
        </contact>
      </surface>
    </collision>
  </link>
  <joint
    name="joint_w6"
    type="continuous">
    <origin
      xyz="-0.436966864880414 -1.29967694498458 -0.0400738309123618"
      rpy="-1.96389113722143 0 -1.5707963267949" />
    <parent
      link="base_rover_1" />
    <child
      link="wheel_6" />
    <axis
      xyz="-1 0 0" />
  </joint>

   <transmission name="$wheel1_trans">
    <type>transmission_interface/SimpleTransmission</type>
      <actuator name="$wheel1_motor">
        <hardwareInterface>EffortJointInterface</hardwareInterface>
        <mechanicalReduction>1</mechanicalReduction>
      </actuator>
      <joint name="joint_w1">
        <hardwareInterface>hardware_interface/VelocityJointInterface</hardwareInterface>
      </joint>
  </transmission>

     <transmission name="$wheel2_trans">
    <type>transmission_interface/SimpleTransmission</type>
      <actuator name="$wheel2_motor">
        <hardwareInterface>EffortJointInterface</hardwareInterface>
        <mechanicalReduction>1</mechanicalReduction>
      </actuator>
      <joint name="joint_w2">
        <hardwareInterface>hardware_interface/VelocityJointInterface</hardwareInterface>
      </joint>
  </transmission>

     <transmission name="$wheel3_trans">
    <type>transmission_interface/SimpleTransmission</type>
      <actuator name="$wheel3_motor">
        <hardwareInterface>EffortJointInterface</hardwareInterface>
        <mechanicalReduction>1</mechanicalReduction>
      </actuator>
      <joint name="joint_w3">
        <hardwareInterface>hardware_interface/VelocityJointInterface</hardwareInterface>
      </joint>
  </transmission>

     <transmission name="$wheel4_trans">
    <type>transmission_interface/SimpleTransmission</type>
      <actuator name="$wheel4_motor">
        <hardwareInterface>EffortJointInterface</hardwareInterface>
        <mechanicalReduction>1</mechanicalReduction>
      </actuator>
      <joint name="joint_w4">
        <hardwareInterface>hardware_interface/VelocityJointInterface</hardwareInterface>
      </joint>
  </transmission>

     <transmission name="$wheel5_trans">
    <type>transmission_interface/SimpleTransmission</type>
      <actuator name="$wheel5_motor">
        <hardwareInterface>EffortJointInterface</hardwareInterface>
        <mechanicalReduction>1</mechanicalReduction>
      </actuator>
      <joint name="joint_w5">
        <hardwareInterface>hardware_interface/VelocityJointInterface</hardwareInterface>
      </joint>
  </transmission>

     <transmission name="$wheel6_trans">
    <type>transmission_interface/SimpleTransmission</type>
      <actuator name="$wheel6_motor">
        <hardwareInterface>EffortJointInterface</hardwareInterface>
        <mechanicalReduction>1</mechanicalReduction>
      </actuator>
      <joint name="joint_w6">
        <hardwareInterface>hardware_interface/VelocityJointInterface</hardwareInterface>
      </joint>
  </transmission>

<!-- IMU implementation -->
<link name="imu_link"/>

<joint name="imu_joint" type="fixed">
  <parent link="base_rover_1"/>
  <child link="imu_link"/>
  <origin xyz="0.5 -0.85 0.5" rpy="0 0 0" />
</joint>

<gazebo reference="imu_link">
  <gravity>true</gravity>
  <sensor name="imu_sensor" type="imu">
    <always_on>true</always_on>
    <update_rate>100</update_rate>
    <visualize>true</visualize>
    <topic>__default_topic__</topic>
    <plugin filename="libgazebo_ros_imu_sensor.so" name="imu_plugin">
      <topicName>imu</topicName>
      <bodyName>imu_link</bodyName>
      <updateRateHZ>10.0</updateRateHZ>
      <gaussianNoise>0.0</gaussianNoise>
      <xyzOffset>0 0 0</xyzOffset>
      <rpyOffset>0 0 0</rpyOffset>
      <frameName>imu_link</frameName>
      <initialOrientationAsReference>false</initialOrientationAsReference>
    </plugin>
    <pose>0 0 0 0 0 0</pose>
  </sensor>
</gazebo>


  <!-- GPS implementation on rover -->

<gazebo>
  <plugin name="gazebo_ros_gps" filename="libhector_gazebo_ros_gps.so">
    <updateRate>10.0</updateRate>
    <bodyName>base_rover_1</bodyName>
    <frameId>base_rover_1</frameId>
    <topicName>/gps/fix</topicName>
    <velocityTopicName>/gps/fix_velocity</velocityTopicName>
    <referenceLatitude>31.7754</referenceLatitude>
    <referenceLongitude>76.9861</referenceLongitude>
    <referenceHeading>20</referenceHeading>
    <referenceAltitude>10</referenceAltitude>
    <offset>0 0 0</offset>
    <drift>0 0 0</drift>
    <gaussianNoise>0.05 0.05 0.05</gaussianNoise>
    <velocityDrift>0.0001 0.0001 0.0001</velocityDrift>
    <velocityGaussianNoise>0.5 0.5 0.5</velocityGaussianNoise>
</plugin>
</gazebo>

<!-- Camera plugin -->
<link name="base_depth"/>

<joint name="depth_joint" type="fixed">
  <parent link="base_rover_1"/>
  <child link="base_depth"/>
  <origin xyz="0.5 -0.85 0.5" rpy="0 0 0" />
</joint>

<!-- Loading Parameters for D435 Camera-->
<gazebo reference="base_depth">
  <sensor name="real_color" type="camera">
    <pose frame="">0 -0.046 0.004 0 0 0</pose>
    <camera name="real_camera">
      <horizontal_fov>1.047</horizontal_fov>
      <image>
        <width>640</width>
        <height>480</height>
        <format>RGB_INT8</format>
      </image>
      <clip>
        <near>0.1</near>
        <far>100</far>
      </clip>
      <noise>
        <type>gaussian</type>
        <mean>0.0</mean>
        <stddev>0.007</stddev>
      </noise>
    </camera>
    <always_on>1</always_on>
    <update_rate>30</update_rate>
    <visualize>1</visualize>
  </sensor>
  <sensor name="real_depth" type="depth">
    <pose frame="">0 -0.03 0.004 0 0 0</pose>
    <camera name="real_camera">
    <horizontal_fov>1.047</horizontal_fov>
    <image>
      <width>640</width>
      <height>480</height>
    </image>
    <clip>
      <near>0.1</near>
      <far>100</far>
    </clip>
    <noise>
      <type>gaussian</type>
      <mean>0.0</mean>
      <stddev>0.0</stddev>
    </noise>
    </camera>
    <always_on>1</always_on>
    <update_rate>30</update_rate>
    <visualize>0</visualize>
  </sensor>
  <sensor name="real_infrared1" type="camera">
      <pose frame="">0 -0.06 0.004 0 0 0</pose>
      <camera name="real_camera">
      <horizontal_fov>1.047</horizontal_fov>
      <image>
          <width>640</width>
          <height>480</height>
          <format>L_INT8</format>
      </image>
      <clip>
          <near>0.1</near>
          <far>100</far>
      </clip>
      <noise>
          <type>gaussian</type>
          <mean>0.0</mean>
          <stddev>0.05</stddev>
      </noise>
      </camera>
      <always_on>1</always_on>
      <update_rate>30</update_rate>
      <visualize>0</visualize>
  </sensor>
  <sensor name="real_infrared2" type="camera">
      <pose frame="">0 0.01 0.004 0 0 0</pose>
      <camera name="real_camera">
      <horizontal_fov>1.047</horizontal_fov>
      <image>
          <width>640</width>
          <height>480</height>
          <format>L_INT8</format>
      </image>
      <clip>
          <near>0.1</near>
          <far>100</far>
      </clip>
      <noise>
          <type>gaussian</type>
          <mean>0.0</mean>
          <stddev>0.05</stddev>
      </noise>
      </camera>
      <always_on>1</always_on>
      <update_rate>30</update_rate>
      <visualize>0</visualize>
  </sensor>
</gazebo>

<gazebo>
  <plugin name="real_d435" filename="librealsense_gazebo_plugin.so">
    <colorTopicName>/camera/color/image_raw</colorTopicName>
    <colorCameraInfoTopicName>/camera/color/camera_info</colorCameraInfoTopicName>
    <depthTopicName>/camera/depth/image_raw</depthTopicName>
    <depthCameraInfoTopicName>/camera/depth/camera_info</depthCameraInfoTopicName>
    <infrared1TopicName>/camera/depth/image_raw</infrared1TopicName>
    <infrared1CameraInfoTopicName>/camera/depth/camera_info</infrared1CameraInfoTopicName>
    <infrared2TopicName>/camera/depth/image_raw</infrared2TopicName>
    <infrared2CameraInfoTopicName>/camera/depth/camera_info</infrared2CameraInfoTopicName>
    <pointCloudTopicName>/camera/depth/points</pointCloudTopicName>
    <colorOpticalframeName>base_depth</colorOpticalframeName>
    <depthOpticalframeName>base_depth</depthOpticalframeName>
    <infrared1OpticalframeName>base_depth</infrared1OpticalframeName>
    <infrared2OpticalframeName>base_depth</infrared2OpticalframeName>
    <robotNamespace/>
  </plugin>
</gazebo>

<gazebo>
  <plugin name="gazebo_ros_control" filename= "libgazebo_ros_control.so">
    <robotNamespace>/</robotNamespace>
    <legacyModeNS>true</legacyModeNS>
  </plugin>
</gazebo>

</robot>